Workbook

Sheet Dashboard
B1: Funding Shock Stress Test: Communities In Schools of Chicago
B2: ="Tab 5 - Dashboard | FY2021-FY2025 actual (Form 990), FY2026-FY2028 forecast | Active scenario: "&Scenarios!C5 -> Tab 5 - Dashboard | FY2021-FY2025 actual (Form 990), FY2026-FY2028 forecast | Active scenario: Base
B4: FY2025 revenue | D4: FY2025 deficit | F4: Unrestricted runway, FY2025 | H4: Runway, end FY2028 | J4: Break-even gift | L4: Program expense ratio, FY2025
B5: =Inputs!G17 -> 6964065 | D5: =Inputs!G26 -> -1109954 | F5: =Historical!G38 -> 9.5070809 | H5: =Forecast!E41 -> 4.3647792 | J5: =INDEX(Scenarios!C33:G33,Scenarios!C6) -> 7198598.6 | L5: =Historical!G22 -> 0.70722957
B6: ="Down "&TEXT(-Historical!G6,"0%")&" vs FY2024" -> Down 15% vs FY2024 | D6: ="Margin "&TEXT(Historical!G32,"0%") -> Margin -16% | F6: ="Down from "&TEXT(Historical!D38,"0.0")&" mo in FY2022" -> Down from 15.1 mo in FY2022 | H6: ="Active scenario: "&Scenarios!C5 -> Active scenario: Base | J6: ="Every "&Scenarios!H17&" yrs vs "&TEXT(Scenarios!H16/1000000,"$0.0")&"M assumed" -> Every 4 yrs vs $5.0M assumed | L6: ="Guideline: 75%+" -> Guideline: 75%+
B58: How to read this: FY2026-FY2028 follow the scenario picked on the Scenarios tab (cell C5). Runway = unrestricted net assets / monthly expenses. Source: CIS of Chicago Form 990s, FY2021-FY2025.
A65: CHART DATA (linked to the other tabs; the charts read from here)
A66: Fiscal year | B66: FY2021 | C66: FY2022 | D66: FY2023 | E66: FY2024 | F66: FY2025 | G66: FY2026F | H66: FY2027F | I66: FY2028F
A67: Total revenue | B67: =Inputs!C17 -> 4386114 | C67: =Inputs!D17 -> 9274759 | D67: =Inputs!E17 -> 11092506 | E67: =Inputs!F17 -> 8228926 | F67: =Inputs!G17 -> 6964065 | G67: =Forecast!C29 -> 7120180.9 | H67: =Forecast!D29 -> 12280980 | I67: =Forecast!E29 -> 7446603.6
A68: Total expenses | B68: =Inputs!C24 -> 5272685 | C68: =Inputs!D24 -> 5841559 | D68: =Inputs!E24 -> 6256478 | E68: =Inputs!F24 -> 7774695 | F68: =Inputs!G24 -> 8074019 | G68: =Forecast!C31 -> 8558460.1 | H68: =Forecast!D31 -> 9071967.7 | I68: =Forecast!E31 -> 9616285.8
A69: Months of unrestricted reserves | B69: =Historical!C38 -> 6.7327322 | C69: =Historical!D38 -> 15.098261 | D69: =Historical!E38 -> 13.274273 | E69: =Historical!F38 -> 9.5781584 | F69: =Historical!G38 -> 9.5070809 | G69: =Forecast!C41 -> 6.9523022 | H69: =Forecast!D41 -> 5.8431812 | I69: =Forecast!E41 -> 4.3647792
A70: Reserve floor (months) | B70: =Inputs!$C$59 -> 3 | C70: =Inputs!$C$59 -> 3 | D70: =Inputs!$C$59 -> 3 | E70: =Inputs!$C$59 -> 3 | F70: =Inputs!$C$59 -> 3 | G70: =Inputs!$C$59 -> 3 | H70: =Inputs!$C$59 -> 3 | I70: =Inputs!$C$59 -> 3
A71: Government grants | B71: =Inputs!C13 -> 1632069 | C71: =Inputs!D13 -> 42688 | D71: =Inputs!E13 -> 163214 | E71: =Inputs!F13 -> 580383 | F71: =Inputs!G13 -> 989248
A72: Other contributions | B72: =Inputs!C15 -> 2182750 | C72: =Inputs!D15 -> 8540130 | D72: =Inputs!E15 -> 10055705 | E72: =Inputs!F15 -> 6745098 | F72: =Inputs!G15 -> 5203863
A73: Program service revenue | B73: =Inputs!C16 -> 556500 | C73: =Inputs!D16 -> 698900 | D73: =Inputs!E16 -> 718500 | E73: =Inputs!F16 -> 655750 | F73: =Inputs!G16 -> 560000
A74: Investment & other | B74: =Inputs!C18 -> 14795 | C74: =Inputs!D18 -> -6959 | D74: =Inputs!E18 -> 155087 | E74: =Inputs!F18 -> 247695 | F74: =Inputs!G18 -> 210954
A75: Program services | B75: =Inputs!C21 -> 4038909 | C75: =Inputs!D21 -> 4174201 | D75: =Inputs!E21 -> 4305748 | E75: =Inputs!F21 -> 5609813 | F75: =Inputs!G21 -> 5710185
A76: Management & general | B76: =Inputs!C22 -> 553847 | C76: =Inputs!D22 -> 712251 | D76: =Inputs!E22 -> 907414 | E76: =Inputs!F22 -> 819140 | F76: =Inputs!G22 -> 1027814
A77: Fundraising | B77: =Inputs!C23 -> 679929 | C77: =Inputs!D23 -> 955107 | D77: =Inputs!E23 -> 1043316 | E77: =Inputs!F23 -> 1345742 | F77: =Inputs!G23 -> 1336020
A79: Scenario | B79: Runway, end FY2028 (months) | C79: Reserves, end FY2028
A80: =Scenarios!C9 -> Base | B80: =Scenarios!C29 -> 4.3647792 | C80: =Scenarios!C28 -> 3497747
A81: =Scenarios!D9 -> No major gift | B81: =Scenarios!D29 -> 1.2450716 | C81: =Scenarios!D28 -> 997747.05
A82: =Scenarios!E9 -> Government cut | B82: =Scenarios!E29 -> 2.5130805 | C82: =Scenarios!E28 -> 2013875
A83: =Scenarios!F9 -> Cost discipline | B83: =Scenarios!F29 -> 6.8547678 | C83: =Scenarios!F28 -> 5039795.9
A84: =Scenarios!G9 -> Combined shock | B84: =Scenarios!G29 -> -0.60662708 | C84: =Scenarios!G28 -> -486124.95

Sheet Inputs
A1: Funding Shock Stress Test: Communities In Schools of Chicago
A2: Tab 1 - Inputs & Assumptions | EIN 36-3591326 | Fiscal years end June 30 | Whole US dollars
A4: How to use this tab
A5: 1,234 | B5: Blue text = number from a Form 990 filing (pre-filled from ProPublica, confirm against the filing)
B6: Yellow cell = key assumption (a lever you can change). Rows marked KEY - VERIFY: check against the filing
A7: 1,234 | B7: Black text = formula. Don't type over these.
A8: Data cells still empty: | C8: =COUNTBLANK(C13:G13)+COUNTBLANK(C21:G23)+COUNTBLANK(C25:G25)+COUNTBLANK(C30:G33)+COUNTBLANK(C36:G37)+COUNTBLANK(C43:G43) -> 0
A10: A. HISTORICAL DATA (FORM 990)
A11: Line item | B11: 990 line | C11: FY2021 | D11: FY2022 | E11: FY2023 | F11: FY2024 | G11: FY2025 | H11: Tag | I11: Source / notes
A12: Revenue
A13: Government grants | B13: VIII 1e | C13: 1632069 | D13: 42688 | E13: 163214 | F13: 580383 | G13: 989248 | H13: Filing | I13: KEY - VERIFY: grew from $43k (FY2022) to $989k (FY2025)
A14: Total contributions | B14: VIII 1h | C14: 3814819 | D14: 8582818 | E14: 10218919 | F14: 7325481 | G14: 6193111 | H14: Filing | I14: ProPublica summary; confirm vs filing
A15: Non-government contributions | B15: 1h - 1e | C15: =IF(C13="","Pending",C14-C13) -> 2182750 | D15: =IF(D13="","Pending",D14-D13) -> 8540130 | E15: =IF(E13="","Pending",E14-E13) -> 10055705 | F15: =IF(F13="","Pending",F14-F13) -> 6745098 | G15: =IF(G13="","Pending",G14-G13) -> 5203863 | H15: Formula | I15: Foundations, corporations, individuals
A16: Program service revenue | B16: VIII 2g | C16: 556500 | D16: 698900 | E16: 718500 | F16: 655750 | G16: 560000 | H16: Filing | I16: ProPublica summary; confirm vs filing; Part VIII 2a: 'School service contracts'
A17: Total revenue | B17: I 12 | C17: 4386114 | D17: 9274759 | E17: 11092506 | F17: 8228926 | G17: 6964065 | H17: Filing | I17: ProPublica summary; confirm vs filing
A18: Investment & other revenue (net) | B18: residual | C18: =C17-C14-C16 -> 14795 | D18: =D17-D14-D16 -> -6959 | E18: =E17-E14-E16 -> 155087 | F18: =F17-F14-F16 -> 247695 | G18: =G17-G14-G16 -> 210954 | H18: Formula | I18: Total revenue - contributions - program revenue
A20: Expenses
A21: Program services | B21: IX 25(B) | C21: 4038909 | D21: 4174201 | E21: 4305748 | F21: 5609813 | G21: 5710185 | H21: Filing | I21: KEY - VERIFY: line 25, column B
A22: Management & general | B22: IX 25(C) | C22: 553847 | D22: 712251 | E22: 907414 | F22: 819140 | G22: 1027814 | H22: Filing | I22: KEY - VERIFY: line 25, column C
A23: Fundraising | B23: IX 25(D) | C23: 679929 | D23: 955107 | E23: 1043316 | F23: 1345742 | G23: 1336020 | H23: Filing | I23: KEY - VERIFY: line 25, column D
A24: Total expenses | B24: IX 25(A) | C24: 5272685 | D24: 5841559 | E24: 6256478 | F24: 7774695 | G24: 8074019 | H24: Filing | I24: ProPublica summary; confirm vs filing
A25: Personnel costs (salaries, benefits, payroll tax) | B25: IX 5-10 | C25: 4738906 | D25: 5009910 | E25: 5134981 | F25: 6449042 | G25: 6775145 | H25: Filing | I25: Sum of column A, lines 5-10 (FY2024 reports staff wages on line 6, not 7)
A26: Surplus / (deficit) | C26: =C17-C24 -> -886571 | D26: =D17-D24 -> 3433200 | E26: =E17-E24 -> 4836028 | F26: =F17-F24 -> 454231 | G26: =G17-G24 -> -1109954 | H26: Formula | I26: Total revenue - total expenses
A27: Check: program + M&G + fundraising = total | C27: =IF(COUNT(C21:C23)<3,"Pending",IF(ABS(SUM(C21:C23)-C24)<=1,"OK","CHECK")) -> OK | D27: =IF(COUNT(D21:D23)<3,"Pending",IF(ABS(SUM(D21:D23)-D24)<=1,"OK","CHECK")) -> OK | E27: =IF(COUNT(E21:E23)<3,"Pending",IF(ABS(SUM(E21:E23)-E24)<=1,"OK","CHECK")) -> OK | F27: =IF(COUNT(F21:F23)<3,"Pending",IF(ABS(SUM(F21:F23)-F24)<=1,"OK","CHECK")) -> OK | G27: =IF(COUNT(G21:G23)<3,"Pending",IF(ABS(SUM(G21:G23)-G24)<=1,"OK","CHECK")) -> OK | H27: Check
A29: Balance sheet (end of year)
A30: Cash (non-interest-bearing) | B30: X 1 | C30: 470094 | D30: 759876 | E30: 1277540 | F30: 1494209 | G30: 1481238 | H30: Filing | I30: Form 990 (e-file); tie-out checks passed
A31: Savings & temporary cash investments | B31: X 2 | C31: 799577 | D31: 1130215 | E31: 1121973 | F31: 0 | G31: 0 | H31: Filing | I31: Blank (0) in FY2024-FY2025
A32: Pledges & grants receivable, net | B32: X 3 | C32: 1076282 | D32: 1994297 | E32: 7058262 | F32: 7160474 | G32: 6404033 | H32: Filing | I32: Promised gifts not yet received in cash
A33: Investments - publicly traded securities | B33: X 11 | C33: 2894236 | D33: 4807268 | E33: 3737202 | F33: 5367903 | G33: 5230613 | H33: Filing | I33: Form 990 (e-file); tie-out checks passed
A34: Total assets | B34: X 16 | C34: 5445597 | D34: 8973055 | E34: 14055139 | F34: 14939265 | G34: 13761145 | H34: Filing | I34: ProPublica summary; confirm vs filing
A35: Total liabilities | B35: X 26 | C35: 285627 | D35: 386191 | E35: 610489 | F35: 1009432 | G35: 861696 | H35: Filing | I35: ProPublica summary; confirm vs filing
A36: Net assets WITHOUT donor restrictions | B36: X 27 | C36: 2958298 | D36: 7349782 | E36: 6920850 | F36: 6205605 | G36: 6396696 | H36: Filing | I36: KEY - VERIFY: the freely spendable reserve (end of year)
A37: Net assets WITH donor restrictions | B37: X 28 | C37: 2201672 | D37: 1237082 | E37: 6523800 | F37: 7724228 | G37: 6502753 | H37: Filing | I37: KEY - VERIFY: restricted by donors (end of year)
A38: Total net assets | B38: X 32 | C38: 5159970 | D38: 8586864 | E38: 13444650 | F38: 13929833 | G38: 12899449 | H38: Filing | I38: ProPublica summary; confirm vs filing
A39: Check: assets - liabilities = net assets | C39: =IF(ABS(C34-C35-C38)<=1,"OK","CHECK") -> OK | D39: =IF(ABS(D34-D35-D38)<=1,"OK","CHECK") -> OK | E39: =IF(ABS(E34-E35-E38)<=1,"OK","CHECK") -> OK | F39: =IF(ABS(F34-F35-F38)<=1,"OK","CHECK") -> OK | G39: =IF(ABS(G34-G35-G38)<=1,"OK","CHECK") -> OK | H39: Check
A40: Check: line 27 + line 28 = line 32 | C40: =IF(COUNT(C36:C37)<2,"Pending",IF(ABS(C36+C37-C38)<=1,"OK","CHECK")) -> OK | D40: =IF(COUNT(D36:D37)<2,"Pending",IF(ABS(D36+D37-D38)<=1,"OK","CHECK")) -> OK | E40: =IF(COUNT(E36:E37)<2,"Pending",IF(ABS(E36+E37-E38)<=1,"OK","CHECK")) -> OK | F40: =IF(COUNT(F36:F37)<2,"Pending",IF(ABS(F36+F37-F38)<=1,"OK","CHECK")) -> OK | G40: =IF(COUNT(G36:G37)<2,"Pending",IF(ABS(G36+G37-G38)<=1,"OK","CHECK")) -> OK | H40: Check
A42: Operating data
A43: Number of employees | B43: I 5 | C43: 68 | D43: 70 | E43: 78 | F43: 86 | G43: 102 | H43: Filing | I43: Part I line 5 (W-3 count for the calendar year)
A45: B. FORECAST ASSUMPTIONS (BASE CASE, FY2026-FY2028)
A46: Driver | B46: Unit | C46: Value | D46: Tag | E46: Rationale
...

Sheet Historical
A1: Funding Shock Stress Test: Communities In Schools of Chicago
A2: Tab 2 - Historical Analysis | FY2021-FY2025 | All figures link to the Inputs tab (green = pulled from Inputs, black = calculated here)
A4: 1. GROWTH (YEAR OVER YEAR)
A5: Metric | B5: Unit | C5: FY2021 | D5: FY2022 | E5: FY2023 | F5: FY2024 | G5: FY2025 | H5: How it's calculated / what to look for
A6: Total revenue growth | B6: % | C6: n/a | D6: =Inputs!D17/Inputs!C17-1 -> 1.1145732 | E6: =Inputs!E17/Inputs!D17-1 -> 0.1959886 | F6: =Inputs!F17/Inputs!E17-1 -> -0.25815447 | G6: =Inputs!G17/Inputs!F17-1 -> -0.15370912 | H6: Big swings = reliance on one-time gifts
A7: Contributions growth | B7: % | C7: n/a | D7: =Inputs!D14/Inputs!C14-1 -> 1.2498624 | E7: =Inputs!E14/Inputs!D14-1 -> 0.19062515 | F7: =Inputs!F14/Inputs!E14-1 -> -0.28314521 | G7: =Inputs!G14/Inputs!F14-1 -> -0.15457961
A8: Program service revenue growth | B8: % | C8: n/a | D8: =Inputs!D16/Inputs!C16-1 -> 0.255885 | E8: =Inputs!E16/Inputs!D16-1 -> 0.028044069 | F8: =Inputs!F16/Inputs!E16-1 -> -0.087334725 | G8: =Inputs!G16/Inputs!F16-1 -> -0.14601601
A9: Total expenses growth | B9: % | C9: n/a | D9: =Inputs!D24/Inputs!C24-1 -> 0.10789076 | E9: =Inputs!E24/Inputs!D24-1 -> 0.071028813 | F9: =Inputs!F24/Inputs!E24-1 -> 0.2426632 | G9: =Inputs!G24/Inputs!F24-1 -> 0.038499774 | H9: Steady climb regardless of revenue
A11: 2. FUNDING MIX (% OF TOTAL REVENUE)
A12: Metric | B12: Unit | C12: FY2021 | D12: FY2022 | E12: FY2023 | F12: FY2024 | G12: FY2025 | H12: How it's calculated / what to look for
A13: Contributions | B13: % | C13: =Inputs!C14/Inputs!C17 -> 0.86974917 | D13: =Inputs!D14/Inputs!D17 -> 0.92539526 | E13: =Inputs!E14/Inputs!E17 -> 0.9212453 | F13: =Inputs!F14/Inputs!F17 -> 0.89021107 | G13: =Inputs!G14/Inputs!G17 -> 0.8892954 | H13: Share of revenue from gifts and grants
A14: of which: government grants | B14: % | C14: =IF((Inputs!C13=""),"Pending",Inputs!C13/Inputs!C17) -> 0.37209908 | D14: =IF((Inputs!D13=""),"Pending",Inputs!D13/Inputs!D17) -> 0.0046025994 | E14: =IF((Inputs!E13=""),"Pending",Inputs!E13/Inputs!E17) -> 0.014713898 | F14: =IF((Inputs!F13=""),"Pending",Inputs!F13/Inputs!F17) -> 0.070529617 | G14: =IF((Inputs!G13=""),"Pending",Inputs!G13/Inputs!G17) -> 0.14205037 | H14: Fills in once Part VIII 1e is entered
A15: of which: non-government | B15: % | C15: =IF((Inputs!C13=""),"Pending",(Inputs!C14-Inputs!C13)/Inputs!C17) -> 0.49765008 | D15: =IF((Inputs!D13=""),"Pending",(Inputs!D14-Inputs!D13)/Inputs!D17) -> 0.92079266 | E15: =IF((Inputs!E13=""),"Pending",(Inputs!E14-Inputs!E13)/Inputs!E17) -> 0.9065314 | F15: =IF((Inputs!F13=""),"Pending",(Inputs!F14-Inputs!F13)/Inputs!F17) -> 0.81968145 | G15: =IF((Inputs!G13=""),"Pending",(Inputs!G14-Inputs!G13)/Inputs!G17) -> 0.74724504 | H15: Foundations, corporations, individuals
A16: Program service revenue | B16: % | C16: =Inputs!C16/Inputs!C17 -> 0.12687769 | D16: =Inputs!D16/Inputs!D17 -> 0.075355058 | E16: =Inputs!E16/Inputs!E17 -> 0.064773461 | F16: =Inputs!F16/Inputs!F17 -> 0.079688406 | G16: =Inputs!G16/Inputs!G17 -> 0.080412805 | H16: Fees / contracts (e.g. schools)
A17: Investment & other revenue | B17: % | C17: =Inputs!C18/Inputs!C17 -> 0.0033731453 | D17: =Inputs!D18/Inputs!D17 -> -0.00075031599 | E17: =Inputs!E18/Inputs!E17 -> 0.013981241 | F17: =Inputs!F18/Inputs!F17 -> 0.030100526 | G17: =Inputs!G18/Inputs!G17 -> 0.030291791
A18: Total | B18: % | C18: =C13+C16+C17 -> 1 | D18: =D13+D16+D17 -> 1 | E18: =E13+E16+E17 -> 1 | F18: =F13+F16+F17 -> 1 | G18: =G13+G16+G17 -> 1 | H18: Should equal 100%
A20: 3. HOW THE MONEY IS SPENT
A21: Metric | B21: Unit | C21: FY2021 | D21: FY2022 | E21: FY2023 | F21: FY2024 | G21: FY2025 | H21: How it's calculated / what to look for
A22: Program expense ratio | B22: % | C22: =IF((Inputs!C21=""),"Pending",Inputs!C21/Inputs!C24) -> 0.76600612 | D22: =IF((Inputs!D21=""),"Pending",Inputs!D21/Inputs!D24) -> 0.71456969 | E22: =IF((Inputs!E21=""),"Pending",Inputs!E21/Inputs!E24) -> 0.68820637 | F22: =IF((Inputs!F21=""),"Pending",Inputs!F21/Inputs!F24) -> 0.72154766 | G22: =IF((Inputs!G21=""),"Pending",Inputs!G21/Inputs!G24) -> 0.70722957 | H22: Program / total expenses. Watchdogs look for 75%+
A23: Management & general ratio | B23: % | C23: =IF((Inputs!C22=""),"Pending",Inputs!C22/Inputs!C24) -> 0.10504079 | D23: =IF((Inputs!D22=""),"Pending",Inputs!D22/Inputs!D24) -> 0.12192824 | E23: =IF((Inputs!E22=""),"Pending",Inputs!E22/Inputs!E24) -> 0.14503591 | F23: =IF((Inputs!F22=""),"Pending",Inputs!F22/Inputs!F24) -> 0.10535976 | G23: =IF((Inputs!G22=""),"Pending",Inputs!G22/Inputs!G24) -> 0.12729893
A24: Fundraising ratio | B24: % | C24: =IF((Inputs!C23=""),"Pending",Inputs!C23/Inputs!C24) -> 0.12895309 | D24: =IF((Inputs!D23=""),"Pending",Inputs!D23/Inputs!D24) -> 0.16350207 | E24: =IF((Inputs!E23=""),"Pending",Inputs!E23/Inputs!E24) -> 0.16675772 | F24: =IF((Inputs!F23=""),"Pending",Inputs!F23/Inputs!F24) -> 0.17309258 | G24: =IF((Inputs!G23=""),"Pending",Inputs!G23/Inputs!G24) -> 0.1654715
A25: Cost to raise $1 of contributions | B25: $ | C25: =IF((Inputs!C23=""),"Pending",Inputs!C23/Inputs!C14) -> 0.17823362 | D25: =IF((Inputs!D23=""),"Pending",Inputs!D23/Inputs!D14) -> 0.11128128 | E25: =IF((Inputs!E23=""),"Pending",Inputs!E23/Inputs!E14) -> 0.10209651 | F25: =IF((Inputs!F23=""),"Pending",Inputs!F23/Inputs!F14) -> 0.18370698 | G25: =IF((Inputs!G23=""),"Pending",Inputs!G23/Inputs!G14) -> 0.2157268 | H25: Fundraising expense / contributions. Lower is better
A26: Personnel share of expenses | B26: % | C26: =IF((Inputs!C25=""),"Pending",Inputs!C25/Inputs!C24) -> 0.89876524 | D26: =IF((Inputs!D25=""),"Pending",Inputs!D25/Inputs!D24) -> 0.85763235 | E26: =IF((Inputs!E25=""),"Pending",Inputs!E25/Inputs!E24) -> 0.82074627 | F26: =IF((Inputs!F25=""),"Pending",Inputs!F25/Inputs!F24) -> 0.82949132 | G26: =IF((Inputs!G25=""),"Pending",Inputs!G25/Inputs!G24) -> 0.83912919 | H26: Social-worker model: expect a high share
A27: Expense per employee | B27: $ | C27: =IF((Inputs!C43=""),"Pending",Inputs!C24/Inputs!C43) -> 77539.485 | D27: =IF((Inputs!D43=""),"Pending",Inputs!D24/Inputs!D43) -> 83450.843 | E27: =IF((Inputs!E43=""),"Pending",Inputs!E24/Inputs!E43) -> 80211.256 | F27: =IF((Inputs!F43=""),"Pending",Inputs!F24/Inputs!F43) -> 90403.43 | G27: =IF((Inputs!G43=""),"Pending",Inputs!G24/Inputs!G43) -> 79157.049
A29: 4. OPERATING RESULTS
A30: Metric | B30: Unit | C30: FY2021 | D30: FY2022 | E30: FY2023 | F30: FY2024 | G30: FY2025 | H30: How it's calculated / what to look for
A31: Surplus / (deficit) | B31: $ | C31: =Inputs!C26 -> -886571 | D31: =Inputs!D26 -> 3433200 | E31: =Inputs!E26 -> 4836028 | F31: =Inputs!F26 -> 454231 | G31: =Inputs!G26 -> -1109954 | H31: From Inputs row 26
A32: Operating margin | B32: % | C32: =C31/Inputs!C17 -> -0.20213132 | D32: =D31/Inputs!D17 -> 0.37016595 | E32: =E31/Inputs!E17 -> 0.43597254 | F32: =F31/Inputs!F17 -> 0.055199305 | G32: =G31/Inputs!G17 -> -0.15938306 | H32: Surplus / total revenue
A34: 5. RESERVES AND RUNWAY
A35: Metric | B35: Unit | C35: FY2021 | D35: FY2022 | E35: FY2023 | F35: FY2024 | G35: FY2025 | H35: How it's calculated / what to look for
A36: Monthly expenses | B36: $ | C36: =Inputs!C24/12 -> 439390.42 | D36: =Inputs!D24/12 -> 486796.58 | E36: =Inputs!E24/12 -> 521373.17 | F36: =Inputs!F24/12 -> 647891.25 | G36: =Inputs!G24/12 -> 672834.92 | H36: Total expenses / 12
A37: Months covered: total net assets | B37: months | C37: =Inputs!C38/C36 -> 11.743474 | D37: =Inputs!D38/D36 -> 17.639532 | E37: =Inputs!E38/E36 -> 25.787 | F37: =Inputs!F38/F36 -> 21.500264 | G37: =Inputs!G38/G36 -> 19.171789 | H37: Looks strong, but includes donor-restricted money
A38: Months covered: UNRESTRICTED net assets | B38: months | C38: =IF((Inputs!C36=""),"Pending",Inputs!C36/C36) -> 6.7327322 | D38: =IF((Inputs!D36=""),"Pending",Inputs!D36/D36) -> 15.098261 | E38: =IF((Inputs!E36=""),"Pending",Inputs!E36/E36) -> 13.274273 | F38: =IF((Inputs!F36=""),"Pending",Inputs!F36/F36) -> 9.5781584 | G38: =IF((Inputs!G36=""),"Pending",Inputs!G36/G36) -> 9.5070809 | H38: KEY: the realistic runway (Part X line 27)
A39: Months covered: cash, savings & investments | B39: months | C39: =IF((Inputs!C30="")+(Inputs!C31="")+(Inputs!C33=""),"Pending",(Inputs!C30+Inputs!C31+Inputs!C33)/C36) -> 9.476554 | D39: =IF((Inputs!D30="")+(Inputs!D31="")+(Inputs!D33=""),"Pending",(Inputs!D30+Inputs!D31+Inputs!D33)/D36) -> 13.758024 | E39: =IF((Inputs!E30="")+(Inputs!E31="")+(Inputs!E33=""),"Pending",(Inputs!E30+Inputs!E31+Inputs!E33)/E36) -> 11.770293 | F39: =IF((Inputs!F30="")+(Inputs!F31="")+(Inputs!F33=""),"Pending",(Inputs!F30+Inputs!F31+Inputs!F33)/F36) -> 10.591457 | G39: =IF((Inputs!G30="")+(Inputs!G31="")+(Inputs!G33=""),"Pending",(Inputs!G30+Inputs!G31+Inputs!G33)/G36) -> 9.9754796 | H39: Liquid assets only (excludes pledges not yet received)
A40: Restricted share of net assets | B40: % | C40: =IF((Inputs!C37=""),"Pending",Inputs!C37/Inputs!C38) -> 0.4266831 | D40: =IF((Inputs!D37=""),"Pending",Inputs!D37/Inputs!D38) -> 0.1440668 | E40: =IF((Inputs!E37=""),"Pending",Inputs!E37/Inputs!E38) -> 0.4852339 | F40: =IF((Inputs!F37=""),"Pending",Inputs!F37/Inputs!F38) -> 0.55450973 | G40: =IF((Inputs!G37=""),"Pending",Inputs!G37/Inputs!G38) -> 0.50411091 | H40: How much of the reserve donors have tied up
A41: Pledges receivable, % of total assets | B41: % | C41: =IF((Inputs!C32=""),"Pending",Inputs!C32/Inputs!C34) -> 0.19764261 | D41: =IF((Inputs!D32=""),"Pending",Inputs!D32/Inputs!D34) -> 0.22225396 | E41: =IF((Inputs!E32=""),"Pending",Inputs!E32/Inputs!E34) -> 0.50218372 | F41: =IF((Inputs!F32=""),"Pending",Inputs!F32/Inputs!F34) -> 0.47930564 | G41: =IF((Inputs!G32=""),"Pending",Inputs!G32/Inputs!G34) -> 0.46537065 | H41: High = gifts booked as revenue but not yet received in cash
A42: Unrestricted months above / (below) reserve floor | B42: months | C42: =IF(ISNUMBER(C38),C38-Inputs!$C$59,"Pending") -> 3.7327322 | D42: =IF(ISNUMBER(D38),D38-Inputs!$C$59,"Pending") -> 12.098261 | E42: =IF(ISNUMBER(E38),E38-Inputs!$C$59,"Pending") -> 10.274273 | F42: =IF(ISNUMBER(F38),F38-Inputs!$C$59,"Pending") -> 6.5781584 | G42: =IF(ISNUMBER(G38),G38-Inputs!$C$59,"Pending") -> 6.5070809 | H42: Compared with the reserve floor on Inputs
A44: 6. FIVE-YEAR SUMMARY (FY2021-FY2025)
A45: Metric | B45: Unit | C45: Value | H45: What it tells you
A46: Revenue growth (CAGR) | B46: % / year | C46: =(Inputs!G17/Inputs!C17)^(1/4)-1 -> 0.12252423 | H46: Starts from a low FY2021, so read it with the volatility below
...

Sheet Forecast
A1: Funding Shock Stress Test: Communities In Schools of Chicago
A2: Tab 3 - Forecast FY2026-FY2028 | FY2025 = actual from the Form 990 | Green = linked from another tab, black = calculated here
A4: DRIVERS IN USE (from the active scenario on the Scenarios tab)
A5: Driver | C5: Value | F5: Source
A6: Non-government recurring contributions, FY2025 base | C6: =Scenarios!H11 -> 5203863 | F6: Scenarios tab, live column (Base case = Inputs C47)
A7: Non-government recurring growth | C7: =Scenarios!H12 -> 0.03 | F7: Scenarios tab, live column (Base case = Inputs C48)
A8: Government grants, FY2025 base | C8: =Scenarios!H13 -> 989248 | F8: Scenarios tab, live column (Base case = Inputs C49)
A9: Government grants growth | C9: =Scenarios!H14 -> 0 | F9: Scenarios tab, live column (Base case = Inputs C50)
A10: Include major one-time gifts? (1 = yes) | C10: =Scenarios!H15 -> 1 | F10: Scenarios tab, live column (Base case = Inputs C51)
A11: Major one-time gift size | C11: =Scenarios!H16 -> 5000000 | F11: Scenarios tab, live column (Base case = Inputs C52)
A12: Major gift frequency (years) / years to spread each gift | C12: =Scenarios!H17 -> 4 | F12: Scenarios tab, live column (Base case = Inputs C53)
A13: Last major-gift year | C13: =Scenarios!H18 -> 2023 | F13: Scenarios tab, live column (Base case = Inputs C54)
A14: Program service revenue growth | C14: =Scenarios!H19 -> 0 | F14: Scenarios tab, live column (Base case = Inputs C55)
A15: Investment & other revenue ($ / year) | C15: =Scenarios!H20 -> 210954 | F15: Scenarios tab, live column (Base case = Inputs C56)
A16: Expense growth | C16: =Scenarios!H21 -> 0.06 | F16: Scenarios tab, live column (Base case = Inputs C57)
A17: Reserve floor (months of expenses) | C17: =Scenarios!H22 -> 3 | F17: Scenarios tab, live column (Base case = Inputs C59)
A19: PROJECTION ($)
A20: Fiscal year | B20: FY2025 Actual | C20: FY2026 | D20: FY2027 | E20: FY2028 | F20: How it's calculated
A21: Year number (helper for gift timing) | B21: 2025 | C21: =B21+1 -> 2026 | D21: =C21+1 -> 2027 | E21: =D21+1 -> 2028
A22: Revenue
A23: Non-government recurring contributions | B23: =Inputs!G14-Inputs!G13 -> 5203863 | C23: =$C$6*(1+$C$7)^(C$21-$B$21) -> 5359978.9 | D23: =$C$6*(1+$C$7)^(D$21-$B$21) -> 5520778.3 | E23: =$C$6*(1+$C$7)^(E$21-$B$21) -> 5686401.6 | F23: FY2025 base grown at the non-government growth rate
A24: Government grants | B24: =Inputs!G13 -> 989248 | C24: =$C$8*(1+$C$9)^(C$21-$B$21) -> 989248 | D24: =$C$8*(1+$C$9)^(D$21-$B$21) -> 989248 | E24: =$C$8*(1+$C$9)^(E$21-$B$21) -> 989248 | F24: FY2025 base grown at the government growth rate
A25: Program service revenue (school contracts) | B25: =Inputs!G16 -> 560000 | C25: =$B$25*(1+$C$14)^(C$21-$B$21) -> 560000 | D25: =$B$25*(1+$C$14)^(D$21-$B$21) -> 560000 | E25: =$B$25*(1+$C$14)^(E$21-$B$21) -> 560000 | F25: FY2025 actual grown at the program revenue growth rate
A26: Investment & other revenue | B26: =Inputs!G18 -> 210954 | C26: =$C$15 -> 210954 | D26: =$C$15 -> 210954 | E26: =$C$15 -> 210954 | F26: Held flat
A27: Recurring revenue | B27: =SUM(B23:B26) -> 6964065 | C27: =SUM(C23:C26) -> 7120180.9 | D27: =SUM(D23:D26) -> 7280980.3 | E27: =SUM(E23:E26) -> 7446603.6 | F27: Everything except one-time gifts
A28: Major one-time gift (booked as revenue) | B28: 0 | C28: =IF(AND($C$10=1,MOD(C$21-$C$13,$C$12)=0),$C$11,0) -> 0 | D28: =IF(AND($C$10=1,MOD(D$21-$C$13,$C$12)=0),$C$11,0) -> 5000000 | E28: =IF(AND($C$10=1,MOD(E$21-$C$13,$C$12)=0),$C$11,0) -> 0 | F28: Booked in full the year it is pledged: every N years after the last gift
A29: Total revenue (as reported) | B29: =B27+B28 -> 6964065 | C29: =C27+C28 -> 7120180.9 | D29: =D27+D28 -> 12280980 | E29: =E27+E28 -> 7446603.6 | F29: Recurring revenue + one-time gift
A30: Expenses
A31: Total expenses | B31: =Inputs!G24 -> 8074019 | C31: =B31*(1+$C$16) -> 8558460.1 | D31: =C31*(1+$C$16) -> 9071967.7 | E31: =D31*(1+$C$16) -> 9616285.8 | F31: Prior year x (1 + expense growth)
A32: Results
A33: Structural surplus / (deficit) before one-time gifts | B33: =B27-B31 -> -1109954 | C33: =C27-C31 -> -1438279.2 | D33: =D27-D31 -> -1790987.5 | E33: =E27-E31 -> -2169682.2 | F33: KEY: recurring revenue - expenses. Shows whether the base budget pays for itself
A34: Reported surplus / (deficit) | B34: =B29-B31 -> -1109954 | C34: =C29-C31 -> -1438279.2 | D34: =D29-D31 -> 3209012.5 | E34: =E29-E31 -> -2169682.2 | F34: What the Form 990 would show (includes the one-time gift)
A35: Structural margin | B35: =B33/B27 -> -0.15938306 | C35: =C33/C27 -> -0.20200038 | D35: =D33/D27 -> -0.24598164 | E35: =E33/E27 -> -0.29136534 | F35: Structural surplus / recurring revenue
A36: Unrestricted reserves (the freely spendable cushion)
A37: Unrestricted net assets, beginning of year | C37: =B39 -> 6396696 | D37: =C39 -> 4958416.8 | E37: =D39 -> 4417429.3 | F37: Prior year's ending balance
A38: + Major gift released to operations | C38: =SUMPRODUCT($C$28:C28*((C$21-$C$21:C$21)<$C$12))/$C$12 -> 0 | D38: =SUMPRODUCT($C$28:D28*((D$21-$C$21:D$21)<$C$12))/$C$12 -> 1250000 | E38: =SUMPRODUCT($C$28:E28*((E$21-$C$21:E$21)<$C$12))/$C$12 -> 1250000 | F38: Each gift is a multi-year pledge, spread evenly over N years starting the year it is booked
A39: Unrestricted net assets, end of year | B39: =Inputs!G36 -> 6396696 | C39: =C37+C33+C38 -> 4958416.8 | D39: =D37+D33+D38 -> 4417429.3 | E39: =E37+E33+E38 -> 3497747 | F39: Beginning + structural surplus + gift released
A40: Monthly expenses | B40: =B31/12 -> 672834.92 | C40: =C31/12 -> 713205.01 | D40: =D31/12 -> 755997.31 | E40: =E31/12 -> 801357.15 | F40: Total expenses / 12
A41: Months of unrestricted reserves | B41: =B39/B40 -> 9.5070809 | C41: =C39/C40 -> 6.9523022 | D41: =D39/D40 -> 5.8431812 | E41: =E39/E40 -> 4.3647792 | F41: KEY: the runway
A42: Months above / (below) the reserve floor | B42: =B41-$C$17 -> 6.5070809 | C42: =C41-$C$17 -> 3.9523022 | D42: =D41-$C$17 -> 2.8431812 | E42: =E41-$C$17 -> 1.3647792 | F42: Negative = below the floor
...

Sheet Scenarios
A1: Funding Shock Stress Test: Communities In Schools of Chicago
A2: Tab 4 - Scenarios | Pick a scenario in the yellow cell; the Forecast tab updates. All five scenarios are also calculated side by side below.
A4: SCENARIO SELECTOR
A5: Active scenario (drives the Forecast tab) | C5: Base | D5: Click the cell and use the dropdown arrow
A6: Scenario number (helper) | C6: =MATCH(C5,C9:G9,0) -> 1
A8: SCENARIO DRIVERS (green = linked to Base, blue = scenario override)
A9: Driver | C9: Base | D9: No major gift | E9: Government cut | F9: Cost discipline | G9: Combined shock | H9: LIVE (in use) | I9: Notes
A10: What changes | C10: Inputs tab assumptions | D10: No new large gift | E10: Government grants cut (row 24) | F10: Expenses grow 3%, major gifts continue | G10: No new gift AND government cut
A11: Non-government recurring contributions, FY2025 base | C11: =Inputs!C47 -> 5203863 | D11: =$C11 -> 5203863 | E11: =$C11 -> 5203863 | F11: =$C11 -> 5203863 | G11: =$C11 -> 5203863 | H11: =INDEX(C11:G11,$C$6) -> 5203863
A12: Non-government recurring growth | C12: =Inputs!C48 -> 0.03 | D12: =$C12 -> 0.03 | E12: =$C12 -> 0.03 | F12: =$C12 -> 0.03 | G12: =$C12 -> 0.03 | H12: =INDEX(C12:G12,$C$6) -> 0.03
A13: Government grants, FY2025 base | C13: =Inputs!C49 -> 989248 | D13: =$C13 -> 989248 | E13: =$C13*(1-$C$24) -> 494624 | F13: =$C13 -> 989248 | G13: =$C13*(1-$C$24) -> 494624 | H13: =INDEX(C13:G13,$C$6) -> 989248 | I13: Cut applied to the FY2025 base
A14: Government grants growth | C14: =Inputs!C50 -> 0 | D14: =$C14 -> 0 | E14: =$C14 -> 0 | F14: =$C14 -> 0 | G14: =$C14 -> 0 | H14: =INDEX(C14:G14,$C$6) -> 0
A15: Include major one-time gifts? (1 = yes) | C15: =Inputs!C51 -> 1 | D15: 0 | E15: =$C15 -> 1 | F15: =$C15 -> 1 | G15: 0 | H15: =INDEX(C15:G15,$C$6) -> 1 | I15: 0 = no new major gift
A16: Major one-time gift size | C16: =Inputs!C52 -> 5000000 | D16: =$C16 -> 5000000 | E16: =$C16 -> 5000000 | F16: =$C16 -> 5000000 | G16: =$C16 -> 5000000 | H16: =INDEX(C16:G16,$C$6) -> 5000000
A17: Major gift frequency (years) | C17: =Inputs!C53 -> 4 | D17: =$C17 -> 4 | E17: =$C17 -> 4 | F17: =$C17 -> 4 | G17: =$C17 -> 4 | H17: =INDEX(C17:G17,$C$6) -> 4
A18: Last major-gift year | C18: =Inputs!C54 -> 2023 | D18: =$C18 -> 2023 | E18: =$C18 -> 2023 | F18: =$C18 -> 2023 | G18: =$C18 -> 2023 | H18: =INDEX(C18:G18,$C$6) -> 2023
A19: Program service revenue growth | C19: =Inputs!C55 -> 0 | D19: =$C19 -> 0 | E19: =$C19 -> 0 | F19: =$C19 -> 0 | G19: =$C19 -> 0 | H19: =INDEX(C19:G19,$C$6) -> 0
A20: Investment & other revenue ($ / year) | C20: =Inputs!C56 -> 210954 | D20: =$C20 -> 210954 | E20: =$C20 -> 210954 | F20: =$C20 -> 210954 | G20: =$C20 -> 210954 | H20: =INDEX(C20:G20,$C$6) -> 210954
A21: Expense growth | C21: =Inputs!C57 -> 0.06 | D21: =$C21 -> 0.06 | E21: =$C21 -> 0.06 | F21: 0.03 | G21: =$C21 -> 0.06 | H21: =INDEX(C21:G21,$C$6) -> 0.06 | I21: Cost discipline caps growth at 3%
A22: Reserve floor (months of expenses) | C22: =Inputs!C59 -> 3 | D22: =$C22 -> 3 | E22: =$C22 -> 3 | F22: =$C22 -> 3 | G22: =$C22 -> 3 | H22: =INDEX(C22:G22,$C$6) -> 3
A24: Government grants cut (Government cut and Combined shock) | C24: 0.5 | D24: Lever: 50% = government grants fall by half from FY2026 (about -$495k a year)
A26: SCENARIO RESULTS (FY2026-FY2028)
A27: Metric | C27: =C9 -> Base | D27: =D9 -> No major gift | E27: =E9 -> Government cut | F27: =F9 -> Cost discipline | G27: =G9 -> Combined shock | I27: What it means
A28: Unrestricted reserves, end of FY2028 | C28: =E48 -> 3497747 | D28: =E58 -> 997747.05 | E28: =E68 -> 2013875 | F28: =E78 -> 5039795.9 | G28: =E88 -> -486124.95 | I28: The freely spendable cushion left
A29: Months of runway, end of FY2028 | C29: =E49 -> 4.3647792 | D29: =E59 -> 1.2450716 | E29: =E69 -> 2.5130805 | F29: =E79 -> 6.8547678 | G29: =E89 -> -0.60662708 | I29: KEY: compare with the 3-month floor
A30: Lowest runway in FY2026-FY2028 (months) | C30: =MIN(C49:E49) -> 4.3647792 | D30: =MIN(C59:E59) -> 1.2450716 | E30: =MIN(C69:E69) -> 2.5130805 | F30: =MIN(C79:E79) -> 6.8547678 | G30: =MIN(C89:E89) -> -0.60662708
A31: First year below the reserve floor | C31: =IFERROR("FY"&INDEX($C$40:$E$40,MATCH("BELOW",C50:E50,0)),"None") -> None | D31: =IFERROR("FY"&INDEX($C$40:$E$40,MATCH("BELOW",C60:E60,0)),"None") -> FY2028 | E31: =IFERROR("FY"&INDEX($C$40:$E$40,MATCH("BELOW",C70:E70,0)),"None") -> FY2028 | F31: =IFERROR("FY"&INDEX($C$40:$E$40,MATCH("BELOW",C80:E80,0)),"None") -> None | G31: =IFERROR("FY"&INDEX($C$40:$E$40,MATCH("BELOW",C90:E90,0)),"None") -> FY2027 | I31: None = stays above the floor
A32: Cumulative structural deficit, FY2026-FY2028 | C32: =SUM(C46:E46) -> -5398949 | D32: =SUM(C56:E56) -> -5398949 | E32: =SUM(C66:E66) -> -6882821 | F32: =SUM(C76:E76) -> -3856900.1 | G32: =SUM(C86:E86) -> -6882821 | I32: Recurring revenue minus expenses, three years combined
A33: Break-even gift needed every N years | C33: =-AVERAGE(C46:E46)*C$17 -> 7198598.6 | D33: =-AVERAGE(C56:E56)*D$17 -> 7198598.6 | E33: =-AVERAGE(C66:E66)*E$17 -> 9177094.6 | F33: =-AVERAGE(C76:E76)*F$17 -> 5142533.5 | G33: =-AVERAGE(C86:E86)*G$17 -> 9177094.6 | I33: KEY: average structural deficit x gift frequency. Compare with the gift size in row 16
A34: Recurring revenue increase needed to balance FY2026 | C34: =-C46/C43 -> 0.20200038 | D34: =-C56/C53 -> 0.20200038 | E34: =-C66/C63 -> 0.29173446 | F34: =-C76/C73 -> 0.1679815 | G34: =-C86/C83 -> 0.29173446 | I34: Or the equivalent cut in FY2026 expenses
A35: Check: live scenario matches the Forecast tab | C35: =IF(AND(ABS(INDEX(C28:G28,$C$6)-Forecast!E39)<=1,ABS(INDEX(C29:G29,$C$6)-Forecast!E41)<0.01),"OK","CHECK") -> OK
A38: CALCULATION ENGINE (same logic as the Forecast tab, run for every scenario at once)
A39: Fiscal year | B39: FY2025A | C39: FY2026 | D39: FY2027 | E39: FY2028
A40: Year number (helper) | B40: 2025 | C40: 2026 | D40: 2027 | E40: 2028
A42: =C$9 -> Base
A43: Recurring revenue | C43: =$C$11*(1+$C$12)^(C$40-$B$40)+$C$13*(1+$C$14)^(C$40-$B$40)+Forecast!$B$25*(1+$C$19)^(C$40-$B$40)+$C$20 -> 7120180.9 | D43: =$C$11*(1+$C$12)^(D$40-$B$40)+$C$13*(1+$C$14)^(D$40-$B$40)+Forecast!$B$25*(1+$C$19)^(D$40-$B$40)+$C$20 -> 7280980.3 | E43: =$C$11*(1+$C$12)^(E$40-$B$40)+$C$13*(1+$C$14)^(E$40-$B$40)+Forecast!$B$25*(1+$C$19)^(E$40-$B$40)+$C$20 -> 7446603.6
A44: Major one-time gift (booked) | C44: =IF(AND($C$15=1,MOD(C$40-$C$18,$C$17)=0),$C$16,0) -> 0 | D44: =IF(AND($C$15=1,MOD(D$40-$C$18,$C$17)=0),$C$16,0) -> 5000000 | E44: =IF(AND($C$15=1,MOD(E$40-$C$18,$C$17)=0),$C$16,0) -> 0
A45: Total expenses | C45: =Forecast!$B$31*(1+$C$21)^(C$40-$B$40) -> 8558460.1 | D45: =Forecast!$B$31*(1+$C$21)^(D$40-$B$40) -> 9071967.7 | E45: =Forecast!$B$31*(1+$C$21)^(E$40-$B$40) -> 9616285.8
A46: Structural surplus / (deficit) | C46: =C43-C45 -> -1438279.2 | D46: =D43-D45 -> -1790987.5 | E46: =E43-E45 -> -2169682.2
A47: Major gift released to operations | C47: =SUMPRODUCT($C44:C44*((C$40-$C$40:C$40)<$C$17))/$C$17 -> 0 | D47: =SUMPRODUCT($C44:D44*((D$40-$C$40:D$40)<$C$17))/$C$17 -> 1250000 | E47: =SUMPRODUCT($C44:E44*((E$40-$C$40:E$40)<$C$17))/$C$17 -> 1250000
...
